<?xml version="1.0"?>
<robot name="mm_mobile">
  <link name="base_link">
    <visual>
      <origin xyz="0 0 0" rpy="0 0 0"/>
      <geometry>
        <box size="0.5 0.3 0.4"/>
      </geometry>
    </visual>
    <collision>
      <origin xyz="0 0 0" rpy="0 0 0"/>
      <geometry>
        <box size="0.5 0.3 0.4"/>
      </geometry>
    </collision>
  </link>

  <link name="left_wheel">
    <visual>
      <origin xyz="0 0 0" rpy="1.5708 0 0"/>
      <geometry>
        <cylinder radius="0.1" length="0.05"/>
      </geometry>
    </visual>
    <collision>
      <origin xyz="0 0 0" rpy="1.5708 0 0"/>
      <geometry>
        <cylinder radius="0.1" length="0.05"/>
      </geometry>
    </collision>
  </link>

  <link name="right_wheel">
    <visual>
      <origin xyz="0 0 0" rpy="1.5708 0 0"/>
      <geometry>
        <cylinder radius="0.1" length="0.05"/>
      </geometry>
    </visual>
    <collision>
      <origin xyz="0 0 0" rpy="1.5708 0 0"/>
      <geometry>
        <cylinder radius="0.1" length="0.05"/>
      </geometry>
    </collision>
  </link>

  <link name="upper_arm_link">
    <visual>
      <origin xyz="0.25 0 0" rpy="0 0 0"/>
      <geometry>
        <box size="0.5 0.08 0.08"/>
      </geometry>
    </visual>
    <collision>
      <origin xyz="0.25 0 0" rpy="0 0 0"/>
      <geometry>
        <box size="0.5 0.08 0.08"/>
      </geometry>
    </collision>
  </link>

  <link name="forearm_link">
    <visual>
      <origin xyz="0.2 0 0" rpy="0 0 0"/>
      <geometry>
        <box size="0.4 0.06 0.06"/>
      </geometry>
    </visual>
    <collision>
      <origin xyz="0.2 0 0" rpy="0 0 0"/>
      <geometry>
        <box size="0.4 0.06 0.06"/>
      </geometry>
    </collision>
  </link>

  <joint name="left_wheel_joint" type="continuous">
    <parent link="base_link"/>
    <child link="left_wheel"/>
    <origin xyz="0 -0.15 0.225" rpy="0 0 0"/>
    <axis xyz="0 0 1"/>
  </joint>

  <joint name="right_wheel_joint" type="continuous">
    <parent link="base_link"/>
    <child link="right_wheel"/>
    <origin xyz="0 -0.15 -0.225" rpy="0 0 0"/>
    <axis xyz="0 0 1"/>
  </joint>

  <joint name="shoulder_joint" type="revolute">
    <parent link="base_link"/>
    <child link="upper_arm_link"/>
    <origin xyz="0 0.15 0" rpy="0 0 0"/>
    <axis xyz="0 1 0"/>
  </joint>

  <joint name="elbow_joint" type="revolute">
    <parent link="upper_arm_link"/>
    <child link="forearm_link"/>
    <origin xyz="0.5 0 0" rpy="0 0 0"/>
    <axis xyz="0 1 0"/>
  </joint>
</robot>
